Workbook

Sheet ОСНОВА
A1: Дата | B1: РФ | C1: Ангарские | D1: Гольяново | E1: Кузьминки | F1: Кусково | G1: Олимпийка | H1: Царицыно | I1: Измайлово | J1: Троицк | K1: Печатники | L1: Екатерининский | M1: ЗИЛ | N1: Вешняки | O1: Некрасовка | P1: Люблино | Q1: Альметьевск | R1: Щёлково | S1: Ленск | T1: Орехово- Зуево | U1: Тверь | V1: Иваново | W1: Хабаровск | X1: В.Новгород | Y1: Саранск | Z1: Пенза | AA1: Валдай | AB1: Подольск | AC1: Гомель | AD1: Гродно | AE1: Брест | AF1: Белград | AG1: НовиСад | AH1: S95&F | AI1: ИТОГ | AJ1: Среднее в РФ | AK1: Среднее | AL1: Среднее в РБ | AN1: Примечание
A2: Минимально | C2: =MIN(C5:C227) -> 9 | D2: =MIN(D5:D227) -> 3 | E2: =MIN(E5:E227) -> 34 | F2: =MIN(F5:F227) -> 12 | G2: =MIN(G5:G227) -> 1 | H2: =MIN(H5:H227) -> 10 | I2: =MIN(I5:I227) -> 10 | J2: =MIN(J5:J227) -> 6 | ... AH2: =MIN(AH5:AH227) -> 4 | AI2: =MIN(AI30:AI227) -> 60
A3: Максимально | C3: =max(C5:C232) -> 90 | D3: =max(D5:D232) -> 41 | E3: =max(E5:E232) -> 845 | F3: =max(F5:F232) -> 132 | G3: =max(G5:G232) -> 74 | H3: =max(H5:H232) -> 98 | I3: =max(I5:I232) -> 179 | J3: =max(J5:J232) -> 800 | ... AI3: =max(AI5:AI232) -> 1542
A4: СРЕДНЕЕ | C4: =AVERAGE(C$5:C230) -> 32.254545 | D4: =AVERAGE(D$5:D230) -> 12.348148 | E4: =AVERAGE(E$5:E230) -> 134.43439 | F4: =AVERAGE(F$5:F230) -> 38.866667 | G4: =AVERAGE(G$5:G230) -> 12.981043 | H4: =AVERAGE(H$5:H230) -> 37.11 | I4: =AVERAGE(I$5:I230) -> 42.576355 | J4: =AVERAGE(J$5:J230) -> 37.302469 | ... AG4: =AVERAGE(AG$5:AG230) -> 16.293233 | AH4: =AVERAGE(AH$48:AH230) -> 113.66667 | AI4: =AVERAGE(AI$48:AI230) -> 470.76111 | AJ4: =AVERAGE(AJ$30:AJ230) -> 37.484072 | AK4: =AVERAGE(AK$30:AK230) -> 35.854624
B5: =COUNT(C5:AB5) -> 0 | AI5: =SUM(C5:AH5) -> 0 | AJ5: =SUM(C5:AB5)/B5 -> #DIV/0! | AK5: =AI5/COUNT(C5:AH5) -> #DIV/0!
A6: 46151 | B6: =COUNT(C6:AB6) -> 24 | C6: 44 | D6: 13 | E6: 160 | F6: 52 | G6: 14 | H6: 49 | I6: 77 | K6: 25 | L6: 10 | M6: 23 | N6: 9 | O6: 23 | P6: 58 | R6: 43 | S6: 15 | T6: 31 | U6: 41 | V6: 90 | W6: 15 | X6: 63 | Y6: 53 | Z6: 53 | AA6: 9 | AB6: 34 | AC6: 23 | AD6: 16 | AE6: 29 | AF6: 23 | AG6: 17 | AI6: =SUM(C6:AH6) -> 1112 | AJ6: =SUM(C6:AB6)/B6 -> 41.833333 | AK6: =AI6/COUNT(C6:AH6) -> 38.344828
A7: 46144 | B7: =COUNT(C7:AB7) -> 25 | C7: 45 | D7: 12 | E7: 101 | F7: 37 | G7: 15 | H7: 35 | I7: 39 | J7: 27 | K7: 31 | L7: 5 | M7: 23 | N7: 13 | O7: 25 | P7: 47 | R7: 18 | S7: 14 | T7: 6 | U7: 39 | V7: 41 | W7: 63 | X7: 68 | Y7: 38 | Z7: 33 | AA7: 10 | AB7: 38 | AD7: 13 | AE7: 34 | AF7: 18 | AG7: 12 | AI7: =SUM(C7:AH7) -> 900 | AJ7: =SUM(C7:AB7)/B7 -> 32.92 | AK7: =AI7/COUNT(C7:AH7) -> 31.034483
A8: 46137 | B8: =COUNT(C8:AB8) -> 26 | C8: 43 | D8: 13 | E8: 101 | F8: 30 | G8: 13 | H8: 38 | I8: 35 | J8: 16 | K8: 25 | L8: 11 | M8: 15 | N8: 12 | O8: 26 | P8: 55 | Q8: 5 | R8: 13 | S8: 19 | T8: 13 | U8: 47 | V8: 31 | W8: 37 | X8: 102 | Y8: 40 | Z8: 33 | AA8: 9 | AB8: 30 | AC8: 11 | AD8: 20 | AE8: 25 | AF8: 21 | AG8: 10 | AI8: =SUM(C8:AH8) -> 899 | AJ8: =SUM(C8:AB8)/B8 -> 31.230769 | AK8: =AI8/COUNT(C8:AH8) -> 29 | AN8: московский полумарафон
A9: 46130 | B9: =COUNT(C9:AB9) -> 26 | C9: 36 | D9: 14 | E9: 100 | F9: 30 | G9: 12 | H9: 42 | I9: 55 | J9: 21 | K9: 19 | L9: 3 | M9: 13 | N9: 4 | O9: 18 | P9: 309 | Q9: 8 | R9: 34 | S9: 24 | T9: 17 | U9: 46 | V9: 50 | W9: 5 | X9: 124 | Y9: 50 | Z9: 55 | AA9: 8 | AB9: 28 | AC9: 14 | AD9: 13 | AE9: 19 | AF9: 14 | AG9: 10 | AI9: =SUM(C9:AH9) -> 1195 | AJ9: =SUM(C9:AB9)/B9 -> 43.269231 | AK9: =AI9/COUNT(C9:AH9) -> 38.548387
A10: 46123 | B10: =COUNT(C10:AB10) -> 26 | C10: 46 | D10: 14 | E10: 152 | F10: 71 | G10: 12 | H10: 31 | I10: 39 | J10: 15 | K10: 22 | L10: 24 | M10: 15 | N10: 9 | O10: 25 | P10: 37 | Q10: 12 | R10: 15 | S10: 14 | T10: 18 | U10: 54 | V10: 54 | W10: 8 | X10: 114 | Y10: 30 | Z10: 50 | AA10: 6 | AB10: 19 | AC10: 16 | AD10: 22 | AE10: 39 | AF10: 23 | AG10: 11 | AI10: =SUM(C10:AH10) -> 1017 | AJ10: =SUM(C10:AB10)/B10 -> 34.846154 | AK10: =AI10/COUNT(C10:AH10) -> 32.806452
A11: 46116 | B11: =COUNT(C11:AB11) -> 26 | C11: 49 | D11: 21 | E11: 128 | F11: 41 | G11: 58 | H11: 43 | I11: 57 | J11: 21 | K11: 121 | L11: 8 | M11: 15 | N11: 13 | O11: 19 | P11: 57 | Q11: 9 | R11: 18 | S11: 13 | T11: 19 | U11: 38 | V11: 59 | W11: 16 | X11: 62 | Y11: 24 | Z11: 45 | AA11: 4 | AB11: 30 | AC11: 25 | AD11: 37 | AE11: 35 | AF11: 17 | AG11: 14 | AI11: =SUM(C11:AH11) -> 1116 | AJ11: =SUM(C11:AB11)/B11 -> 38 | AK11: =AI11/COUNT(C11:AH11) -> 36
A12: 46109 | B12: =COUNT(C12:AB12) -> 26 | C12: 51 | D12: 8 | E12: 150 | F12: 25 | G12: 14 | H12: 44 | I12: 164 | J12: 15 | K12: 17 | L12: 10 | M12: 11 | N12: 13 | O12: 9 | P12: 66 | Q12: 6 | R12: 20 | S12: 14 | T12: 15 | U12: 45 | V12: 47 | W12: 19 | X12: 62 | Y12: 40 | Z12: 41 | AA12: 10 | AB12: 38 | AC12: 33 | AD12: 29 | AE12: 33 | AF12: 9 | AG12: 5 | AI12: =SUM(C12:AH12) -> 1063 | AJ12: =SUM(C12:AB12)/B12 -> 36.692308 | AK12: =AI12/COUNT(C12:AH12) -> 34.290323
A13: 46102 | B13: =COUNT(C13:AB13) -> 26 | C13: 41 | D13: 16 | E13: 126 | F13: 40 | G13: 13 | H13: 43 | I13: 35 | J13: 23 | K13: 31 | L13: 7 | M13: 16 | N13: 18 | O13: 15 | P13: 63 | Q13: 10 | R13: 20 | S13: 15 | T13: 37 | U13: 48 | V13: 38 | W13: 15 | X13: 78 | Y13: 34 | Z13: 31 | AA13: 7 | AB13: 29 | AC13: 20 | AD13: 23 | AE13: 31 | AF13: 23 | AG13: 18 | AI13: =SUM(C13:AH13) -> 964 | AJ13: =SUM(C13:AB13)/B13 -> 32.653846 | AK13: =AI13/COUNT(C13:AH13) -> 31.096774
A14: 46095 | B14: =COUNT(C14:AB14) -> 26 | C14: 63 | D14: 22 | E14: 127 | F14: 25 | G14: 16 | H14: 60 | I14: 40 | J14: 17 | K14: 28 | L14: 6 | M14: 30 | N14: 15 | O14: 7 | P14: 45 | Q14: 7 | R14: 13 | S14: 16 | T14: 11 | U14: 36 | V14: 38 | W14: 15 | X14: 81 | Y14: 43 | Z14: 36 | AA14: 6 | AB14: 27 | AC14: 20 | AD14: 30 | AE14: 34 | AF14: 19 | AG14: 21 | AI14: =SUM(C14:AH14) -> 954 | AJ14: =SUM(C14:AB14)/B14 -> 31.923077 | AK14: =AI14/COUNT(C14:AH14) -> 30.774194
A15: 46088 | B15: =COUNT(C15:AB15) -> 26 | C15: 57 | D15: 13 | E15: 144 | F15: 35 | G15: 9 | H15: 40 | I15: 33 | J15: 22 | K15: 18 | L15: 10 | M15: 8 | N15: 11 | O15: 12 | P15: 37 | Q15: 6 | R15: 12 | S15: 10 | T15: 10 | U15: 37 | V15: 38 | W15: 35 | X15: 67 | Y15: 34 | Z15: 28 | AA15: 3 | AB15: 40 | AC15: 25 | AD15: 27 | AE15: 30 | AF15: 16 | AG15: 17 | AI15: =SUM(C15:AH15) -> 884 | AJ15: =SUM(C15:AB15)/B15 -> 29.576923 | AK15: =AI15/COUNT(C15:AH15) -> 28.516129
A16: 46081 | B16: =COUNT(C16:AB16) -> 25 | C16: 38 | D16: 10 | E16: 103 | F16: 30 | G16: 9 | H16: 43 | I16: 28 | J16: 13 | K16: 26 | L16: 4 | M16: 13 | N16: 6 | O16: 8 | P16: 41 | Q16: 7 | R16: 12 | S16: 12 | T16: 8 | U16: 12 | V16: 34 | W16: 12 | Y16: 34 | Z16: 30 | AA16: 4 | AB16: 55 | AC16: 12 | AD16: 17 | AE16: 31 | AF16: 26 | AG16: 10 | AI16: =SUM(C16:AH16) -> 688 | AJ16: =SUM(C16:AB16)/B16 -> 23.68 | AK16: =AI16/COUNT(C16:AH16) -> 22.933333
A17: 46074 | B17: =COUNT(C17:AB17) -> 26 | C17: 36 | D17: 8 | E17: 86 | F17: 39 | G17: 8 | H17: 32 | I17: 27 | J17: 19 | K17: 20 | L17: 6 | M17: 21 | N17: 5 | O17: 7 | P17: 51 | Q17: 4 | R17: 11 | S17: 14 | T17: 11 | U17: 27 | V17: 37 | W17: 15 | X17: 51 | Y17: 29 | Z17: 30 | AA17: 3 | AB17: 25 | AC17: 18 | AD17: 25 | AE17: 26 | AF17: 27 | AG17: 8 | AI17: =SUM(C17:AH17) -> 726 | AJ17: =SUM(C17:AB17)/B17 -> 23.923077 | AK17: =AI17/COUNT(C17:AH17) -> 23.419355
A18: 46067 | B18: =COUNT(C18:AB18) -> 26 | C18: 31 | D18: 14 | E18: 60 | F18: 25 | G18: 5 | H18: 21 | I18: 36 | J18: 22 | K18: 15 | L18: 2 | M18: 16 | N18: 5 | O18: 9 | P18: 196 | Q18: 3 | R18: 11 | S18: 15 | T18: 9 | U18: 35 | V18: 31 | W18: 11 | X18: 183 | Y18: 29 | Z18: 24 | AA18: 4 | AB18: 18 | AC18: 9 | AD18: 23 | AE18: 22 | AF18: 22 | AG18: 12 | AI18: =SUM(C18:AH18) -> 918 | AJ18: =SUM(C18:AB18)/B18 -> 31.923077 | AK18: =AI18/COUNT(C18:AH18) -> 29.612903
A19: 46060 | B19: =COUNT(C19:AB19) -> 25 | C19: 29 | D19: 7 | E19: 787 | F19: 12 | G19: 9 | H19: 19 | I19: 23 | J19: 17 | K19: 8 | L19: 2 | M19: 5 | N19: 5 | O19: 6 | Q19: 4 | R19: 7 | S19: 16 | T19: 9 | U19: 28 | V19: 47 | W19: 11 | X19: 77 | Y19: 34 | Z19: 43 | AA19: 8 | AB19: 22 | AC19: 15 | AD19: 15 | AE19: 22 | AF19: 24 | AG19: 9 | AH19: 45 | AI19: =SUM(C19:AH19) -> 1365 | AJ19: =SUM(C19:AB19)/B19 -> 49.4 | AK19: =AI19/COUNT(C19:AH19) -> 44.032258 | AN19: забег маяков
A20: 46053 | B20: =COUNT(C20:AB20)+AH20 -> 25 | C20: 34 | D20: 10 | E20: 105 | F20: 13 | G20: 8 | H20: 26 | I20: 17 | J20: 9 | K20: 16 | L20: 4 | M20: 9 | N20: 11 | O20: 11 | Q20: 5 | R20: 7 | S20: 10 | T20: 9 | U20: 18 | V20: 30 | W20: 2 | X20: 48 | Y20: 19 | Z20: 32 | AA20: 3 | AB20: 14 | AC20: 6 | AD20: 23 | AE20: 15 | AF20: 27 | AG20: 14 | AI20: =SUM(C20:AH20) -> 555 | AJ20: =SUM(C20:AB20)/B20 -> 18.8 | AK20: =AI20/COUNT(C20:AH20) -> 18.5 | AN20: в москве холодно -20
A21: 46046 | B21: =COUNT(C21:AB21)+AH21 -> 24 | C21: 42 | D21: 8 | E21: 96 | F21: 20 | G21: 10 | H21: 21 | I21: 27 | J21: 17 | K21: 19 | L21: 5 | M21: 8 | N21: 6 | Q21: 6 | R21: 8 | S21: 8 | T21: 9 | U21: 22 | V21: 27 | W21: 7 | X21: 61 | Y21: 12 | Z21: 17 | AA21: 4 | AB21: 17 | AC21: 16 | AD21: 18 | AE21: 20 | AF21: 24 | AG21: 11 | AI21: =SUM(C21:AH21) -> 566 | AJ21: =SUM(C21:AB21)/B21 -> 19.875 | AK21: =AI21/COUNT(C21:AH21) -> 19.517241
A22: 46039 | B22: =COUNT(C22:AB22)+AH22 -> 24 | C22: 29 | D22: 13 | E22: 138 | F22: 33 | G22: 11 | H22: 49 | I22: 29 | J22: 19 | K22: 20 | L22: 20 | M22: 10 | N22: 10 | Q22: 3 | R22: 9 | S22: 8 | T22: 10 | U22: 23 | V22: 31 | W22: 12 | X22: 54 | Y22: 14 | Z22: 25 | AA22: 4 | AB22: 17 | AC22: 12 | AD22: 20 | AE22: 16 | AF22: 21 | AG22: 5 | AI22: =SUM(C22:AH22) -> 665 | AJ22: =SUM(C22:AB22)/B22 -> 24.625 | AK22: =AI22/COUNT(C22:AH22) -> 22.931034
A23: 46032 | B23: =COUNT(C23:AB23)+AH23 -> 22 | C23: 29 | D23: 7 | E23: 159 | F23: 33 | G23: 14 | H23: 41 | I23: 25 | J23: 18 | K23: 16 | M23: 14 | N23: 9 | Q23: 3 | R23: 10 | S23: 9 | U23: 23 | V23: 33 | W23: 5 | X23: 48 | Y23: 40 | Z23: 31 | AA23: 3 | AB23: 27 | AC23: 11 | AD23: 19 | AE23: 22 | AF23: 15 | AG23: 6 | AI23: =SUM(C23:AH23) -> 670 | AJ23: =SUM(C23:AB23)/B23 -> 27.136364 | AK23: =AI23/COUNT(C23:AH23) -> 24.814815 | AN23: снегопад, 2 отмены
A24: 46025 | B24: =COUNT(C24:AB24)+AH24 -> 24 | C24: 25 | D24: 12 | E24: 111 | F24: 35 | G24: 16 | H24: 37 | I24: 20 | J24: 19 | K24: 13 | L24: 9 | M24: 4 | N24: 9 | Q24: 3 | R24: 9 | S24: 4 | T24: 10 | U24: 36 | V24: 47 | W24: 10 | X24: 50 | Y24: 25 | Z24: 24 | AA24: 11 | AB24: 29 | AC24: 14 | AD24: 18 | AE24: 20 | AF24: 13 | AG24: 10 | AI24: =SUM(C24:AH24) -> 643 | AJ24: =SUM(C24:AB24)/B24 -> 23.666667 | AK24: =AI24/COUNT(C24:AH24) -> 22.172414
A25: 46023 | B25: =COUNT(C25:AB25)+AH25 -> 11 | C25: 39 | E25: 140 | F25: 34 | G25: 34 | H25: 46 | I25: 41 | K25: 34 | M25: 23 | V25: 52 | Y25: 24 | Z25: 16 | AC25: 16 | AE25: 91 | AF25: 27 | AI25: =SUM(C25:AH25) -> 617 | AJ25: =SUM(C25:AB25)/B25 -> 43.909091 | AK25: =AI25/COUNT(C25:AH25) -> 44.071429 | AN25: дпололнительный страт 1 января
A26: 46018 | B26: =COUNT(C26:AB26)+AH26 -> 24 | C26: 68 | D26: 16 | E26: 150 | F26: 42 | G26: 17 | H26: 61 | I26: 49 | J26: 48 | K26: 35 | L26: 7 | M26: 10 | N26: 10 | Q26: 3 | R26: 18 | S26: 11 | T26: 14 | U26: 49 | V26: 37 | W26: 33 | X26: 60 | Y26: 32 | Z26: 35 | AA26: 13 | AB26: 26 | AC26: 19 | AD26: 38 | AE26: 17 | AF26: 23 | AG26: 10 | AI26: =SUM(C26:AH26) -> 951 | AJ26: =SUM(C26:AB26)/B26 -> 35.166667 | AK26: =AI26/COUNT(C26:AH26) -> 32.793103
A27: 46011 | B27: =COUNT(C27:AB27)+AH27 -> 24 | C27: 41 | D27: 10 | E27: 169 | F27: 31 | G27: 17 | H27: 46 | I27: 33 | J27: 19 | K27: 18 | L27: 4 | M27: 8 | N27: 12 | Q27: 3 | R27: 14 | S27: 12 | T27: 8 | U27: 35 | V27: 27 | W27: 10 | X27: 100 | Y27: 41 | Z27: 33 | AA27: 4 | AB27: 19 | AC27: 14 | AD27: 21 | AE27: 10 | AF27: 23 | AG27: 9 | AI27: =SUM(C27:AH27) -> 791 | AJ27: =SUM(C27:AB27)/B27 -> 29.75 | AK27: =AI27/COUNT(C27:AH27) -> 27.275862
A28: 46004 | B28: =COUNT(C28:AB28)+AH28 -> 24 | C28: 43 | D28: 10 | E28: 98 | F28: 94 | G28: 14 | H28: 37 | I28: 36 | J28: 21 | K28: 21 | L28: 10 | M28: 6 | N28: 5 | Q28: 8 | R28: 8 | S28: 12 | T28: 11 | U28: 32 | V28: 42 | W28: 6 | X28: 46 | Y28: 21 | Z28: 26 | AA28: 4 | AB28: 21 | AC28: 26 | AD28: 32 | AE28: 34 | AF28: 16 | AG28: 5 | AI28: =SUM(C28:AH28) -> 745 | AJ28: =SUM(C28:AB28)/B28 -> 26.333333 | AK28: =AI28/COUNT(C28:AH28) -> 25.689655 | AN28: первая большая зима
A29: 45997 | B29: =COUNT(C29:AB29)+AH29 -> 24 | C29: 57 | D29: 16 | E29: 333 | F29: 51 | G29: 19 | H29: 57 | I29: 60 | J29: 26 | K29: 24 | L29: 14 | M29: 21 | N29: 19 | Q29: 7 | R29: 18 | S29: 15 | T29: 18 | U29: 59 | V29: 57 | W29: 9 | X29: 76 | Y29: 52 | Z29: 34 | AA29: 11 | AB29: 35 | AC29: 32 | AD29: 34 | AE29: 33 | AF29: 14 | AG29: 13 | AI29: =SUM(C29:AH29) -> 1214 | AJ29: =SUM(C29:AB29)/B29 -> 45.333333 | AK29: =AI29/COUNT(C29:AH29) -> 41.862069 | AN29: помпоны
A30: 45990 | B30: =COUNT(C30:AB30)+AH30 -> 24 | C30: 47 | D30: 11 | E30: 160 | F30: 50 | G30: 9 | H30: 57 | I30: 41 | J30: 21 | K30: 43 | L30: 11 | M30: 10 | N30: 11 | Q30: 4 | R30: 21 | S30: 10 | T30: 16 | U30: 35 | V30: 38 | W30: 12 | X30: 91 | Y30: 56 | Z30: 37 | AA30: 6 | AB30: 31 | AC30: 31 | AD30: 22 | AE30: 36 | AF30: 15 | AG30: 6 | AI30: =SUM(C30:AH30) -> 938 | AJ30: =SUM(C30:AB30)/B30 -> 34.5 | AK30: =AI30/COUNT(C30:AH30) -> 32.344828
A31: 45983 | B31: =COUNT(C31:AB31)+AH31 -> 24 | C31: 44 | D31: 16 | E31: 169 | F31: 27 | G31: 13 | H31: 39 | I31: 33 | J31: 33 | K31: 43 | L31: 10 | M31: 15 | N31: 12 | Q31: 4 | R31: 17 | S31: 17 | T31: 15 | U31: 40 | V31: 30 | W31: 14 | X31: 76 | Y31: 44 | Z31: 54 | AA31: 9 | AB31: 33 | AC31: 31 | AD31: 29 | AE31: 29 | AF31: 16 | AG31: 8 | AI31: =SUM(C31:AH31) -> 920 | AJ31: =SUM(C31:AB31)/B31 -> 33.625 | AK31: =AI31/COUNT(C31:AH31) -> 31.724138
A32: 45976 | B32: =COUNT(C32:AB32) -> 24 | C32: 47 | D32: 15 | E32: 107 | F32: 24 | G32: 9 | H32: 39 | I32: 29 | J32: 23 | K32: 21 | L32: 5 | M32: 41 | N32: 7 | Q32: 10 | R32: 21 | S32: 17 | T32: 11 | U32: 56 | V32: 36 | W32: 13 | X32: 116 | Y32: 51 | Z32: 47 | AA32: 8 | AB32: 22 | AC32: 28 | AD32: 23 | AE32: 42 | AF32: 25 | AG32: 12 | AI32: =SUM(C32:AH32) -> 905 | AJ32: =SUM(C32:AB32)/B32 -> 32.291667 | AK32: =AI32/COUNT(C32:AH32) -> 31.206897 | AN32: точка сбора 2025
A33: 45969 | B33: =COUNT(C33:AB33) -> 24 | C33: 58 | D33: 22 | E33: 153 | F33: 35 | G33: 16 | H33: 45 | I33: 39 | J33: 25 | K33: 24 | L33: 13 | M33: 17 | N33: 15 | Q33: 8 | R33: 26 | S33: 15 | T33: 23 | U33: 47 | V33: 31 | W33: 13 | X33: 65 | Y33: 67 | Z33: 44 | AA33: 12 | AB33: 25 | AC33: 19 | AD33: 22 | AE33: 40 | AF33: 16 | AG33: 7 | AI33: =SUM(C33:AH33) -> 942 | AJ33: =SUM(C33:AB33)/B33 -> 34.916667 | AK33: =AI33/COUNT(C33:AH33) -> 32.482759
A34: 45962 | B34: =COUNT(C34:AB34) -> 19 | C34: 35 | D34: 15 | E34: 111 | F34: 20 | G34: 4 | H34: 20 | I34: 30 | J34: 15 | K34: 21 | M34: 5 | N34: 5 | Q34: 3 | R34: 12 | S34: 9 | T34: 11 | V34: 22 | Y34: 16 | Z34: 21 | AA34: 13 | AC34: 20 | AD34: 20 | AE34: 38 | AF34: 12 | AG34: 16 | AI34: =SUM(C34:AH34) -> 494 | AJ34: =SUM(C34:AB34)/B34 -> 20.421053 | AK34: =AI34/COUNT(C34:AH34) -> 20.583333 | AN34: рабочая суббота
A35: 45955 | B35: =COUNT(C35:AB35) -> 24 | C35: 47 | D35: 19 | E35: 156 | F35: 42 | G35: 13 | H35: 40 | I35: 49 | J35: 39 | K35: 27 | L35: 14 | M35: 24 | N35: 12 | Q35: 8 | R35: 13 | S35: 17 | T35: 12 | U35: 33 | V35: 38 | W35: 8 | X35: 84 | Y35: 52 | Z35: 54 | AA35: 17 | AB35: 28 | AC35: 6 | AD35: 16 | AE35: 17 | AF35: 27 | AG35: 9 | AI35: =SUM(C35:AH35) -> 921 | AJ35: =SUM(C35:AB35)/B35 -> 35.25 | AK35: =AI35/COUNT(C35:AH35) -> 31.758621
A36: 45948 | B36: =COUNT(C36:AB36) -> 24 | C36: 43 | D36: 9 | E36: 160 | F36: 41 | G36: 8 | H36: 33 | I36: 26 | J36: 34 | K36: 33 | L36: 10 | M36: 12 | N36: 9 | Q36: 11 | R36: 24 | S36: 16 | T36: 27 | U36: 40 | V36: 29 | W36: 1 | X36: 109 | Y36: 56 | Z36: 56 | AA36: 16 | AB36: 30 | AC36: 26 | AD36: 8 | AE36: 52 | AF36: 21 | AG36: 9 | AI36: =SUM(C36:AH36) -> 949 | AJ36: =SUM(C36:AB36)/B36 -> 34.708333 | AK36: =AI36/COUNT(C36:AH36) -> 32.724138
A37: 45941 | B37: =COUNT(C37:AB37) -> 23 | C37: 35 | D37: 8 | E37: 131 | F37: 111 | G37: 19 | H37: 40 | I37: 39 | J37: 36 | K37: 25 | L37: 11 | M37: 16 | Q37: 7 | R37: 10 | S37: 18 | T37: 18 | U37: 43 | V37: 36 | W37: 15 | X37: 86 | Y37: 53 | Z37: 56 | AA37: 15 | AB37: 24 | AC37: 7 | AD37: 20 | AE37: 22 | AF37: 15 | AG37: 15 | AI37: =SUM(C37:AH37) -> 931 | AJ37: =SUM(C37:AB37)/B37 -> 37.043478 | AK37: =AI37/COUNT(C37:AH37) -> 33.25
A38: 45934 | B38: =COUNT(C38:AB38) -> 23 | C38: 47 | D38: 39 | E38: 184 | F38: 48 | G38: 14 | H38: 49 | I38: 52 | J38: 27 | K38: 28 | L38: 8 | M38: 22 | Q38: 5 | R38: 24 | S38: 18 | T38: 33 | U38: 27 | V38: 32 | W38: 5 | X38: 110 | Y38: 59 | Z38: 39 | AA38: 15 | AB38: 20 | AC38: 11 | AD38: 16 | AE38: 39 | AF38: 22 | AG38: 14 | AI38: =SUM(C38:AH38) -> 1007 | AJ38: =SUM(C38:AB38)/B38 -> 39.347826 | AK38: =AI38/COUNT(C38:AH38) -> 35.964286
A39: 45927 | B39: =COUNT(C39:AB39) -> 22 | C39: 39 | D39: 12 | E39: 167 | F39: 79 | G39: 15 | H39: 45 | I39: 54 | J39: 25 | K39: 34 | L39: 14 | M39: 22 | Q39: 6 | R39: 32 | S39: 17 | T39: 19 | U39: 33 | W39: 8 | X39: 100 | Y39: 33 | Z39: 73 | AA39: 15 | AB39: 26 | AC39: 20 | AE39: 40 | AF39: 19 | AG39: 6 | AH39: 15 | AI39: =SUM(C39:AH39) -> 968 | AJ39: =SUM(C39:AB39)/B39 -> 39.454545 | AK39: =AI39/COUNT(C39:AH39) -> 35.851852 | AP39: =AC39+AE39+15 -> 75
A40: 45920 | B40: =COUNT(C40:AB40) -> 23 | C40: 27 | D40: 8 | E40: 127 | F40: 34 | G40: 12 | H40: 23 | I40: 43 | J40: 21 | K40: 18 | L40: 12 | M40: 15 | Q40: 4 | R40: 15 | S40: 9 | T40: 28 | U40: 33 | V40: 19 | W40: 4 | X40: 46 | Y40: 12 | Z40: 38 | AA40: 19 | AB40: 22 | AC40: 19 | AE40: 45 | AF40: 22 | AG40: 19 | AI40: =SUM(C40:AH40) -> 694 | AJ40: =SUM(C40:AB40)/B40 -> 25.608696 | AK40: =AI40/COUNT(C40:AH40) -> 25.703704 | AP40: =AC40+AE40 -> 64
...

Sheet Новички
A1: ='ОСНОВА'!A1 -> Дата | C1: ='ОСНОВА'!C1 -> Ангарские | D1: ='ОСНОВА'!D1 -> Гольяново | E1: ='ОСНОВА'!E1 -> Кузьминки | F1: ='ОСНОВА'!F1 -> Кусково | G1: ='ОСНОВА'!G1 -> Олимпийка | H1: ='ОСНОВА'!H1 -> Царицыно | I1: ='ОСНОВА'!I1 -> Измайлово | J1: ='ОСНОВА'!J1 -> Троицк | ... N1: ='ОСНОВА'!N1 -> Вешняки | O1: Некрасовкка | P1: ='ОСНОВА'!P1 -> Люблино | Q1: ='ОСНОВА'!Q1 -> Альметьевск | R1: ='ОСНОВА'!R1 -> Щёлково | S1: ='ОСНОВА'!S1 -> Ленск | T1: ='ОСНОВА'!T1 -> Орехово- Зуево | U1: ='ОСНОВА'!U1 -> Тверь | V1: ='ОСНОВА'!V1 -> Иваново | W1: ='ОСНОВА'!W1 -> Хабаровск | ... AH1: ='ОСНОВА'!AH1 -> S95&F
A3: 45997 | B3: Участников | C3: ='ОСНОВА'!C29 -> 57 | D3: ='ОСНОВА'!D29 -> 16 | E3: ='ОСНОВА'!E29 -> 333 | F3: ='ОСНОВА'!F29 -> 51 | G3: ='ОСНОВА'!G29 -> 19 | H3: ='ОСНОВА'!H29 -> 57 | I3: ='ОСНОВА'!I29 -> 60 | J3: ='ОСНОВА'!J29 -> 26 | ... N3: ='ОСНОВА'!N29 -> 19 | Q3: ='ОСНОВА'!Q29 -> 7 | R3: ='ОСНОВА'!R29 -> 18 | S3: ='ОСНОВА'!S29 -> 15 | T3: ='ОСНОВА'!T29 -> 18 | U3: ='ОСНОВА'!U29 -> 59 | V3: ='ОСНОВА'!V29 -> 57 | W3: ='ОСНОВА'!W29 -> 9 | X3: ='ОСНОВА'!X29 -> 76 | ... AH3: ='ОСНОВА'!AH29 | AI3: =SUM(C3:AH3) -> 1214
B4: Новичков | C4: 1 | D4: 3 | E4: 37 | F4: 5 | G4: 2 | H4: 4 | I4: 3 | J4: 1 | K4: 3 | L4: 1 | M4: 6 | N4: 3 | Q4: 0 | R4: 3 | S4: 0 | T4: 1 | U4: 4 | V4: 13 | W4: 0 | X4: 8 | Y4: 4 | Z4: 2 | AA4: 1 | AB4: 2 | AC4: 3 | AD4: 6 | AE4: 2 | AF4: 2 | AG4: 1 | AI4: =SUM(C4:AH4) -> 121
B5: % новичков | C5: =C4/C3 -> 0.01754386 | D5: =D4/D3 -> 0.1875 | E5: =E4/E3 -> 0.11111111 | F5: =F4/F3 -> 0.098039216 | G5: =G4/G3 -> 0.10526316 | H5: =H4/H3 -> 0.070175439 | I5: =I4/I3 -> 0.05 | J5: =J4/J3 -> 0.038461538 | ... N5: =N4/N3 -> 0.15789474 | Q5: =Q4/Q3 -> 0 | R5: =R4/R3 -> 0.16666667 | S5: =S4/S3 -> 0 | T5: =T4/T3 -> 0.055555556 | U5: =U4/U3 -> 0.06779661 | V5: =V4/V3 -> 0.22807018 | W5: =W4/W3 -> 0 | X5: =X4/X3 -> 0.10526316 | ... AG5: =AG4/AG3 -> 0.076923077 | AI5: =AI4/AI3 -> 0.099670511
A7: 46004 | B7: Участников | C7: ='ОСНОВА'!C28 -> 43 | D7: ='ОСНОВА'!D28 -> 10 | E7: ='ОСНОВА'!E28 -> 98 | F7: ='ОСНОВА'!F28 -> 94 | G7: ='ОСНОВА'!G28 -> 14 | H7: ='ОСНОВА'!H28 -> 37 | I7: ='ОСНОВА'!I28 -> 36 | J7: ='ОСНОВА'!J28 -> 21 | ... N7: ='ОСНОВА'!N28 -> 5 | Q7: ='ОСНОВА'!Q28 -> 8 | R7: ='ОСНОВА'!R28 -> 8 | S7: ='ОСНОВА'!S28 -> 12 | T7: ='ОСНОВА'!T28 -> 11 | U7: ='ОСНОВА'!U28 -> 32 | V7: ='ОСНОВА'!V28 -> 42 | W7: ='ОСНОВА'!W28 -> 6 | X7: ='ОСНОВА'!X28 -> 46 | ... AG7: ='ОСНОВА'!AG28 -> 5 | AH7: ='ОСНОВА'!AH33 | AI7: =SUM(C7:AH7) -> 745
B8: Новичков | C8: 2 | D8: 0 | E8: 6 | F8: 7 | G8: 1 | H8: 2 | I8: 2 | J8: 0 | K8: 0 | L8: 2 | M8: 0 | N8: 0 | Q8: 1 | R8: 0 | S8: 0 | T8: 0 | V8: 3 | W8: 0 | X8: 2 | Y8: 1 | Z8: 1 | AA8: 1 | AB8: 0 | AC8: 2 | AD8: 20 | AE8: 0 | AF8: 1 | AG8: 0 | AI8: =SUM(C8:AH8) -> 54
B9: % новичков | C9: =C8/C7 -> 0.046511628 | D9: =D8/D7 -> 0 | E9: =E8/E7 -> 0.06122449 | F9: =F8/F7 -> 0.074468085 | G9: =G8/G7 -> 0.071428571 | H9: =H8/H7 -> 0.054054054 | I9: =I8/I7 -> 0.055555556 | J9: =J8/J7 -> 0 | ... N9: =N8/N7 -> 0 | Q9: =Q8/Q7 -> 0.125 | R9: =R8/R7 -> 0 | S9: =S8/S7 -> 0 | T9: =T8/T7 -> 0 | U9: =U8/U7 -> 0 | V9: =V8/V7 -> 0.071428571 | W9: =W8/W7 -> 0 | X9: =X8/X7 -> 0.043478261 | ... AG9: =AG8/AG7 -> 0 | AI9: =AI8/AI7 -> 0.072483221
A11: 46011 | B11: Участников | C11: ='ОСНОВА'!C27 -> 41 | D11: ='ОСНОВА'!D27 -> 10 | E11: ='ОСНОВА'!E27 -> 169 | F11: ='ОСНОВА'!F27 -> 31 | G11: ='ОСНОВА'!G27 -> 17 | H11: ='ОСНОВА'!H27 -> 46 | I11: ='ОСНОВА'!I27 -> 33 | J11: ='ОСНОВА'!J27 -> 19 | ... N11: ='ОСНОВА'!N27 -> 12 | Q11: ='ОСНОВА'!Q27 -> 3 | R11: ='ОСНОВА'!R27 -> 14 | S11: ='ОСНОВА'!S27 -> 12 | T11: ='ОСНОВА'!T27 -> 8 | U11: ='ОСНОВА'!U27 -> 35 | V11: ='ОСНОВА'!V27 -> 27 | W11: ='ОСНОВА'!W27 -> 10 | X11: ='ОСНОВА'!X27 -> 100 | ... AG11: ='ОСНОВА'!AG27 -> 9 | AH11: ='ОСНОВА'!AH37 | AI11: =SUM(C11:AH11) -> 791
B12: Новичков | C12: 2 | D12: 0 | E12: 10 | F12: 1 | G12: 0 | H12: 1 | I12: 0 | J12: 0 | K12: 0 | L12: 1 | M12: 0 | N12: 2 | Q12: 0 | R12: 0 | S12: 0 | T12: 2 | U12: 2 | V12: 2 | W12: 0 | X12: 5 | Y12: 1 | Z12: 0 | AA12: 0 | AB12: 2 | AC12: 1 | AD12: 2 | AE12: 0 | AF12: 1 | AG12: 0 | AI12: =SUM(C12:AH12) -> 35
B13: % новичков | C13: =C12/C11 -> 0.048780488 | D13: =D12/D11 -> 0 | E13: =E12/E11 -> 0.059171598 | F13: =F12/F11 -> 0.032258065 | G13: =G12/G11 -> 0 | H13: =H12/H11 -> 0.02173913 | I13: =I12/I11 -> 0 | J13: =J12/J11 -> 0 | ... N13: =N12/N11 -> 0.16666667 | Q13: =Q12/Q11 -> 0 | R13: =R12/R11 -> 0 | S13: =S12/S11 -> 0 | T13: =T12/T11 -> 0.25 | U13: =U12/U11 -> 0.057142857 | V13: =V12/V11 -> 0.074074074 | W13: =W12/W11 -> 0 | X13: =X12/X11 -> 0.05 | ... AG13: =AG12/AG11 -> 0 | AI13: =AI12/AI11 -> 0.044247788
A15: 46018 | B15: Участников | C15: ='ОСНОВА'!C26 -> 68 | D15: ='ОСНОВА'!D26 -> 16 | E15: ='ОСНОВА'!E26 -> 150 | F15: ='ОСНОВА'!F26 -> 42 | G15: ='ОСНОВА'!G26 -> 17 | H15: ='ОСНОВА'!H26 -> 61 | I15: ='ОСНОВА'!I26 -> 49 | J15: ='ОСНОВА'!J26 -> 48 | ... N15: ='ОСНОВА'!N26 -> 10 | Q15: ='ОСНОВА'!Q26 -> 3 | R15: ='ОСНОВА'!R26 -> 18 | S15: ='ОСНОВА'!S26 -> 11 | T15: ='ОСНОВА'!T26 -> 14 | U15: ='ОСНОВА'!U26 -> 49 | V15: ='ОСНОВА'!V26 -> 37 | W15: ='ОСНОВА'!W26 -> 33 | X15: ='ОСНОВА'!X26 -> 60 | ... AG15: ='ОСНОВА'!AG26 -> 10 | AH15: ='ОСНОВА'!AH41 | AI15: =SUM(C15:AH15) -> 951
B16: Новичков | C16: 1 | D16: 0 | E16: 6 | F16: 1 | G16: 1 | H16: 2 | I16: 5 | J16: 0 | K16: 2 | L16: 1 | M16: 3 | N16: 1 | Q16: 0 | R16: 1 | S16: 0 | T16: 0 | U16: 7 | V16: 0 | W16: 11 | X16: 0 | Y16: 1 | Z16: 0 | AA16: 0 | AB16: 0 | AC16: 2 | AD16: 4 | AE16: 0 | AF16: 3 | AG16: 1 | AI16: =SUM(C16:AH16) -> 53
B17: % новичков | C17: =C16/C15 -> 0.014705882 | D17: =D16/D15 -> 0 | E17: =E16/E15 -> 0.04 | F17: =F16/F15 -> 0.023809524 | G17: =G16/G15 -> 0.058823529 | H17: =H16/H15 -> 0.032786885 | I17: =I16/I15 -> 0.10204082 | J17: =J16/J15 -> 0 | ... N17: =N16/N15 -> 0.1 | Q17: =Q16/Q15 -> 0 | R17: =R16/R15 -> 0.055555556 | S17: =S16/S15 -> 0 | T17: =T16/T15 -> 0 | U17: =U16/U15 -> 0.14285714 | V17: =V16/V15 -> 0 | W17: =W16/W15 -> 0.33333333 | X17: =X16/X15 -> 0 | ... AG17: =AG16/AG15 -> 0.1 | AI17: =AI16/AI15 -> 0.05573081
A19: 46023 | B19: Участников | C19: ='ОСНОВА'!C25 -> 39 | D19: ='ОСНОВА'!D25 | E19: ='ОСНОВА'!E25 -> 140 | F19: ='ОСНОВА'!F25 -> 34 | G19: ='ОСНОВА'!G25 -> 34 | H19: ='ОСНОВА'!H25 -> 46 | I19: ='ОСНОВА'!I25 -> 41 | J19: ='ОСНОВА'!J25 | ... N19: ='ОСНОВА'!N25 | Q19: ='ОСНОВА'!Q25 | R19: ='ОСНОВА'!R25 | S19: ='ОСНОВА'!S25 | T19: ='ОСНОВА'!T25 | U19: ='ОСНОВА'!U25 | V19: ='ОСНОВА'!V25 -> 52 | W19: ='ОСНОВА'!W25 | X19: ='ОСНОВА'!X25 | ... AG19: ='ОСНОВА'!AG25 | AH19: ='ОСНОВА'!AH45 | AI19: =SUM(C19:AH19) -> 617
B20: Новичков | C20: 1 | E20: 4 | F20: 0 | G20: 6 | H20: 3 | I20: 4 | K20: 1 | M20: 4 | V20: 3 | Y20: 1 | Z20: 0 | AC20: 0 | AE20: 47 | AF20: 3 | AI20: =SUM(C20:AH20) -> 77
B21: % новичков | C21: =C20/C19 -> 0.025641026 | D21: =D20/D19 -> #DIV/0! | E21: =E20/E19 -> 0.028571429 | F21: =F20/F19 -> 0 | G21: =G20/G19 -> 0.17647059 | H21: =H20/H19 -> 0.065217391 | I21: =I20/I19 -> 0.097560976 | J21: =J20/J19 -> #DIV/0! | ... N21: =N20/N19 -> #DIV/0! | Q21: =Q20/Q19 -> #DIV/0! | R21: =R20/R19 -> #DIV/0! | S21: =S20/S19 -> #DIV/0! | T21: =T20/T19 -> #DIV/0! | U21: =U20/U19 -> #DIV/0! | V21: =V20/V19 -> 0.057692308 | W21: =W20/W19 -> #DIV/0! | X21: =X20/X19 -> #DIV/0! | ... AG21: =AG20/AG19 -> #DIV/0! | AI21: =AI20/AI19 -> 0.12479741
A23: 46025 | B23: Участников | C23: ='ОСНОВА'!C24 -> 25 | D23: ='ОСНОВА'!D24 -> 12 | E23: ='ОСНОВА'!E24 -> 111 | F23: ='ОСНОВА'!F24 -> 35 | G23: ='ОСНОВА'!G24 -> 16 | H23: ='ОСНОВА'!H24 -> 37 | I23: ='ОСНОВА'!I24 -> 20 | J23: ='ОСНОВА'!J24 -> 19 | ... N23: ='ОСНОВА'!N24 -> 9 | Q23: ='ОСНОВА'!Q24 -> 3 | R23: ='ОСНОВА'!R24 -> 9 | S23: ='ОСНОВА'!S24 -> 4 | T23: ='ОСНОВА'!T24 -> 10 | U23: ='ОСНОВА'!U24 -> 36 | V23: ='ОСНОВА'!V24 -> 47 | W23: ='ОСНОВА'!W24 -> 10 | X23: ='ОСНОВА'!X24 -> 50 | ... AG23: ='ОСНОВА'!AG24 -> 10 | AH23: ='ОСНОВА'!AH49 | AI23: =SUM(C23:AH23) -> 643
B24: Новичков | C24: 0 | D24: 0 | E24: 1 | F24: 1 | G24: 4 | H24: 2 | I24: 1 | J24: 1 | K24: 0 | L24: 2 | M24: 0 | N24: 1 | Q24: 0 | R24: 0 | S24: 0 | T24: 0 | U24: 1 | V24: 1 | W24: 0 | X24: 1 | Y24: 1 | Z24: 1 | AA24: 1 | AB24: 3 | AC24: 0 | AD24: 4 | AE24: 0 | AF24: 0 | AG24: 0 | AI24: =SUM(C24:AH24) -> 26
B25: % новичков | C25: =C24/C23 -> 0 | D25: =D24/D23 -> 0 | E25: =E24/E23 -> 0.009009009 | F25: =F24/F23 -> 0.028571429 | G25: =G24/G23 -> 0.25 | H25: =H24/H23 -> 0.054054054 | I25: =I24/I23 -> 0.05 | J25: =J24/J23 -> 0.052631579 | ... N25: =N24/N23 -> 0.11111111 | Q25: =Q24/Q23 -> 0 | R25: =R24/R23 -> 0 | S25: =S24/S23 -> 0 | T25: =T24/T23 -> 0 | U25: =U24/U23 -> 0.027777778 | V25: =V24/V23 -> 0.021276596 | W25: =W24/W23 -> 0 | X25: =X24/X23 -> 0.02 | ... AG25: =AG24/AG23 -> 0 | AI25: =AI24/AI23 -> 0.040435459
A27: 46032 | B27: Участников | C27: ='ОСНОВА'!C23 -> 29 | D27: ='ОСНОВА'!D23 -> 7 | E27: ='ОСНОВА'!E23 -> 159 | F27: ='ОСНОВА'!F23 -> 33 | G27: ='ОСНОВА'!G23 -> 14 | H27: ='ОСНОВА'!H23 -> 41 | I27: ='ОСНОВА'!I23 -> 25 | J27: ='ОСНОВА'!J23 -> 18 | ... N27: ='ОСНОВА'!N23 -> 9 | Q27: ='ОСНОВА'!Q23 -> 3 | R27: ='ОСНОВА'!R23 -> 10 | S27: ='ОСНОВА'!S23 -> 9 | T27: ='ОСНОВА'!T23 | U27: ='ОСНОВА'!U23 -> 23 | V27: ='ОСНОВА'!V23 -> 33 | W27: ='ОСНОВА'!W23 -> 5 | X27: ='ОСНОВА'!X23 -> 48 | ... AG27: ='ОСНОВА'!AG23 -> 6 | AH27: ='ОСНОВА'!AH53 | AI27: =SUM(C27:AH27) -> 670
B28: Новичков | C28: 1 | D28: 0 | E28: 13 | F28: 4 | G28: 1 | H28: 4 | I28: 1 | J28: 0 | K28: 0 | M28: 1 | N28: 0 | Q28: 0 | R28: 0 | S28: 0 | U28: 2 | V28: 2 | W28: 0 | X28: 0 | Y28: 4 | Z28: 2 | AA28: 0 | AB28: 3 | AC28: 0 | AD28: 0 | AE28: 1 | AF28: 0 | AG28: 0 | AI28: =SUM(C28:AH28) -> 39
B29: % новичков | C29: =C28/C27 -> 0.034482759 | D29: =D28/D27 -> 0 | E29: =E28/E27 -> 0.081761006 | F29: =F28/F27 -> 0.12121212 | G29: =G28/G27 -> 0.071428571 | H29: =H28/H27 -> 0.097560976 | I29: =I28/I27 -> 0.04 | J29: =J28/J27 -> 0 | ... N29: =N28/N27 -> 0 | Q29: =Q28/Q27 -> 0 | R29: =R28/R27 -> 0 | S29: =S28/S27 -> 0 | T29: =T28/T27 -> #DIV/0! | U29: =U28/U27 -> 0.086956522 | V29: =V28/V27 -> 0.060606061 | W29: =W28/W27 -> 0 | X29: =X28/X27 -> 0 | ... AG29: =AG28/AG27 -> 0 | AI29: =AI28/AI27 -> 0.058208955
A31: 46039 | B31: Участников | C31: ='ОСНОВА'!C22 -> 29 | D31: ='ОСНОВА'!D22 -> 13 | E31: ='ОСНОВА'!E22 -> 138 | F31: ='ОСНОВА'!F22 -> 33 | G31: ='ОСНОВА'!G22 -> 11 | H31: ='ОСНОВА'!H22 -> 49 | I31: ='ОСНОВА'!I22 -> 29 | J31: ='ОСНОВА'!J22 -> 19 | ... N31: ='ОСНОВА'!N22 -> 10 | Q31: ='ОСНОВА'!Q22 -> 3 | R31: ='ОСНОВА'!R22 -> 9 | S31: ='ОСНОВА'!S22 -> 8 | T31: ='ОСНОВА'!T22 -> 10 | U31: ='ОСНОВА'!U22 -> 23 | V31: ='ОСНОВА'!V22 -> 31 | W31: ='ОСНОВА'!W22 -> 12 | X31: ='ОСНОВА'!X22 -> 54 | ... AG31: ='ОСНОВА'!AG22 -> 5 | AH31: ='ОСНОВА'!AH57 | AI31: =SUM(C31:AH31) -> 665
B32: Новичков | C32: 1 | D32: 1 | E32: 9 | F32: 0 | G32: 0 | H32: 4 | I32: 1 | J32: 1 | K32: 1 | L32: 1 | M32: 0 | N32: 0 | Q32: 0 | R32: 2 | S32: 0 | T32: 0 | U32: 1 | V32: 0 | W32: 0 | X32: 1 | Y32: 0 | Z32: 1 | AA32: 0 | AB32: 0 | AC32: 0 | AD32: 1 | AE32: 0 | AF32: 1 | AG32: 0 | AI32: =SUM(C32:AH32) -> 26
B33: % новичков | C33: =C32/C31 -> 0.034482759 | D33: =D32/D31 -> 0.076923077 | E33: =E32/E31 -> 0.065217391 | F33: =F32/F31 -> 0 | G33: =G32/G31 -> 0 | H33: =H32/H31 -> 0.081632653 | I33: =I32/I31 -> 0.034482759 | J33: =J32/J31 -> 0.052631579 | ... N33: =N32/N31 -> 0 | Q33: =Q32/Q31 -> 0 | R33: =R32/R31 -> 0.22222222 | S33: =S32/S31 -> 0 | T33: =T32/T31 -> 0 | U33: =U32/U31 -> 0.043478261 | V33: =V32/V31 -> 0 | W33: =W32/W31 -> 0 | X33: =X32/X31 -> 0.018518519 | ... AG33: =AG32/AG31 -> 0 | AI33: =AI32/AI31 -> 0.039097744
A35: 46046 | B35: Участников | C35: ='ОСНОВА'!C21 -> 42 | D35: ='ОСНОВА'!D21 -> 8 | E35: ='ОСНОВА'!E21 -> 96 | F35: ='ОСНОВА'!F21 -> 20 | G35: ='ОСНОВА'!G21 -> 10 | H35: ='ОСНОВА'!H21 -> 21 | I35: ='ОСНОВА'!I21 -> 27 | J35: ='ОСНОВА'!J21 -> 17 | ... N35: ='ОСНОВА'!N21 -> 6 | Q35: ='ОСНОВА'!Q21 -> 6 | R35: ='ОСНОВА'!R21 -> 8 | S35: ='ОСНОВА'!S21 -> 8 | T35: ='ОСНОВА'!T21 -> 9 | U35: ='ОСНОВА'!U21 -> 22 | V35: ='ОСНОВА'!V21 -> 27 | W35: ='ОСНОВА'!W21 -> 7 | X35: ='ОСНОВА'!X21 -> 61 | ... AG35: ='ОСНОВА'!AG21 -> 11 | AH35: ='ОСНОВА'!AH61 | AI35: =SUM(C35:AH35) -> 566
B36: Новичков | C36: 1 | D36: 1 | E36: 4 | F36: 1 | G36: 0 | H36: 2 | I36: 0 | J36: 0 | K36: 0 | L36: 2 | M36: 0 | N36: 0 | Q36: 1 | R36: 0 | S36: 0 | T36: 0 | U36: 2 | V36: 1 | W36: 0 | X36: 1 | Y36: 0 | Z36: 0 | AA36: 0 | AB36: 0 | AC36: 0 | AD36: 2 | AE36: 0 | AF36: 1 | AG36: 1 | AI36: =SUM(C36:AH36) -> 20
B37: % новичков | C37: =C36/C35 -> 0.023809524 | D37: =D36/D35 -> 0.125 | E37: =E36/E35 -> 0.041666667 | F37: =F36/F35 -> 0.05 | G37: =G36/G35 -> 0 | H37: =H36/H35 -> 0.095238095 | I37: =I36/I35 -> 0 | J37: =J36/J35 -> 0 | ... N37: =N36/N35 -> 0 | Q37: =Q36/Q35 -> 0.16666667 | R37: =R36/R35 -> 0 | S37: =S36/S35 -> 0 | T37: =T36/T35 -> 0 | U37: =U36/U35 -> 0.090909091 | V37: =V36/V35 -> 0.037037037 | W37: =W36/W35 -> 0 | X37: =X36/X35 -> 0.016393443 | ... AG37: =AG36/AG35 -> 0.090909091 | AI37: =AI36/AI35 -> 0.035335689
A39: ='ОСНОВА'!A20 -> 46053 | B39: Участников | C39: ='ОСНОВА'!C20 -> 34 | D39: ='ОСНОВА'!D20 -> 10 | E39: ='ОСНОВА'!E20 -> 105 | F39: ='ОСНОВА'!F20 -> 13 | G39: ='ОСНОВА'!G20 -> 8 | H39: ='ОСНОВА'!H20 -> 26 | I39: ='ОСНОВА'!I20 -> 17 | J39: ='ОСНОВА'!J20 -> 9 | ... AH39: ='ОСНОВА'!AH20 | AI39: =SUM(C39:AH39) -> 555
B40: Новичков | C40: 0 | D40: 0 | E40: 3 | F40: 0 | G40: 1 | H40: 0 | I40: 1 | K40: 0 | L40: 0 | M40: 0 | N40: 0 | O40: 6 | Q40: 0 | R40: 0 | T40: 0 | U40: 0 | V40: 0 | W40: 0 | Y40: 1 | Z40: 3 | AA40: 0 | AB40: 0 | AC40: 0 | AD40: 2 | AE40: 0 | AF40: 0 | AG40: 1 | AI40: =SUM(C40:AH40) -> 18
B41: % новичков | C41: =C40/C39 -> 0 | D41: =D40/D39 -> 0 | E41: =E40/E39 -> 0.028571429 | F41: =F40/F39 -> 0 | G41: =G40/G39 -> 0.125 | H41: =H40/H39 -> 0 | I41: =I40/I39 -> 0.058823529 | J41: =J40/J39 -> 0 | ... AG41: =AG40/AG39 -> 0.071428571 | AI41: =AI40/AI39 -> 0.032432432
A43: ='ОСНОВА'!A19 -> 46060 | B43: Участников | C43: ='ОСНОВА'!C19 -> 29 | D43: ='ОСНОВА'!D19 -> 7 | E43: ='ОСНОВА'!E19 -> 787 | F43: ='ОСНОВА'!F19 -> 12 | G43: ='ОСНОВА'!G19 -> 9 | H43: ='ОСНОВА'!H19 -> 19 | I43: ='ОСНОВА'!I19 -> 23 | J43: ='ОСНОВА'!J19 -> 17 | K43: ='ОСНОВА'!K19 -> 8 | L43: 2 | M43: ='ОСНОВА'!M19 -> 5 | N43: ='ОСНОВА'!N19 -> 5 | O43: ='ОСНОВА'!O19 -> 6 | P43: ='ОСНОВА'!P19 | Q43: ='ОСНОВА'!Q19 -> 4 | R43: ='ОСНОВА'!R19 -> 7 | S43: ='ОСНОВА'!S19 -> 16 | T43: ='ОСНОВА'!T19 -> 9 | ... AH43: ='ОСНОВА'!AH19 -> 45 | AI43: =SUM(C43:AH43) -> 1365
B44: Новичков | C44: 0 | D44: 0 | E44: 143 | F44: 0 | G44: 1 | H44: 0 | I44: 1 | J44: 1 | K44: 0 | L44: 1 | M44: 0 | N44: 0 | O44: 3 | P44: 3 | Q44: 0 | R44: 0 | S44: 0 | T44: 0 | U44: 0 | V44: 5 | W44: 0 | X44: 2 | Y44: 4 | Z44: 6 | AA44: 0 | AB44: 0 | AC44: 2 | AD44: 2 | AE44: 1 | AF44: 2 | AG44: 0 | AH44: 23 | AI44: =SUM(C44:AH44) -> 200
B45: % новичков | C45: =C44/C43 -> 0 | D45: =D44/D43 -> 0 | E45: =E44/E43 -> 0.18170267 | F45: =F44/F43 -> 0 | G45: =G44/G43 -> 0.11111111 | H45: =H44/H43 -> 0 | I45: =I44/I43 -> 0.043478261 | J45: =J44/J43 -> 0.058823529 | ... AI45: =AI44/AI43 -> 0.14652015
A47: ='ОСНОВА'!A18 -> 46067 | B47: Участников | C47: ='ОСНОВА'!C18 -> 31 | D47: ='ОСНОВА'!D18 -> 14 | E47: ='ОСНОВА'!E18 -> 60 | F47: ='ОСНОВА'!F18 -> 25 | G47: ='ОСНОВА'!G18 -> 5 | H47: ='ОСНОВА'!H18 -> 21 | I47: ='ОСНОВА'!I18 -> 36 | J47: ='ОСНОВА'!J18 -> 22 | ... R47: ='ОСНОВА'!R18 -> 11 | S47: ='ОСНОВА'!R18 -> 11 | T47: ='ОСНОВА'!S18 -> 15 | U47: ='ОСНОВА'!T18 -> 9 | V47: ='ОСНОВА'!U18 -> 35 | W47: ='ОСНОВА'!V18 -> 31 | X47: ='ОСНОВА'!W18 -> 11 | Y47: ='ОСНОВА'!X18 -> 183 | Z47: ='ОСНОВА'!Y18 -> 29 | ... AG47: ='ОСНОВА'!AF18 -> 22 | AH47: ='ОСНОВА'!AH23 | AI47: =SUM(C47:AH47) -> 917
B48: Новичков | C48: 0 | E48: 6 | O48: 3 | V48: 3 | Y48: 42 | AA48: 0 | AC48: 0 | AD48: 1 | AE48: 0 | AF48: 1 | AG48: 2 | AI48: =SUM(C48:AH48) -> 58
B49: % новичков | C49: =C48/C47 -> 0 | D49: =D48/D47 -> 0 | E49: =E48/E47 -> 0.1 | F49: =F48/F47 -> 0 | G49: =G48/G47 -> 0 | H49: =H48/H47 -> 0 | I49: =I48/I47 -> 0 | J49: =J48/J47 -> 0 | ... AI49: =AI48/AI47 -> 0.063249727
A51: ='ОСНОВА'!A17 -> 46074 | B51: Участников | AI51: =SUM(C51:AH51) -> 0
B52: Новичков | AI52: =SUM(C52:AH52) -> 0
B53: % новичков | C53: =C52/C51 -> #DIV/0! | D53: =D52/D51 -> #DIV/0! | E53: =E52/E51 -> #DIV/0! | F53: =F52/F51 -> #DIV/0! | G53: =G52/G51 -> #DIV/0! | H53: =H52/H51 -> #DIV/0! | I53: =I52/I51 -> #DIV/0! | J53: =J52/J51 -> #DIV/0! | ... AI53: =AI52/AI51 -> #DIV/0!
...

Sheet Лист2
A1: 45857 | B1: Ангарские пруды | C1: 24 | D1: 11 | E1: Роман САМОХВАЛОВ | F1: 0.75138889 | G1: Александра ГОНЧАРОВА | H1: 1.0152778
A2: 45857 | B2: Альметьевск | C2: 9 | D2: 3 | E2: Тимур ГАЛИМОВ | F2: 0.93402778 | G2: Елена КРАСИЛЬНИКОВА | H2: 1.0180556
A3: 45857 | B3: Гольяново | C3: 14 | D3: 7 | E3: Mikhail AGAFONOV | F3: 0.92986111 | G3: Анастасия НЕЧЕСОВА | H3: 1.0222222
A4: 45857 | B4: Валдай | C4: 31 | D4: 5 | E4: Данил МАЛАФЕЕВ | F4: 0.82013889 | G4: Татьяна РЫБИНСКАЯ | H4: 1.0222222
A5: 45857 | B5: Великий Новгород | C5: 86 | D5: 11 | E5: Александр Сова | F5: 0.73125 | G5: Ольга ВОРОБЬЕВА | H5: 0.86319444
A6: 45857 | B6: Иваново | C6: 27 | D6: 4 | E6: Андрей ДАНЬКО | F6: 0.84513889 | G6: Мария УДАЛОВА | H6: 0.94861111
A7: 45857 | B7: Екатерининский | C7: 13 | D7: 20 | E7: Владимир ДУНЯХИН | F7: 0.96180556 | G7: Наталия СИТНИКОВА | H7: 0.96111111
A8: 45857 | B8: Измайлово | C8: 39 | D8: 11 | E8: Ярослав БЕЛОУСОВ | F8: 0.81527778 | G8: Надежда АНФИМОВА | H8: 0.93055556
A9: 45857 | B9: Кузьминки | C9: 777 | D9: 94 | E9: Дмитрий ТИХОНОВ | F9: 0.69722222 | G9: Marina ZAYTSEVA | H9: 0.76527778
A10: 45857 | B10: Кусково | C10: 26 | D10: 17 | E10: Роман БЕЛЬЧИК | F10: 0.72013889 | G10: Елизавета ГОЛУБЕВА | H10: 0.90138889
A11: 45857 | B11: Олимпийская Деревня | C11: 9 | D11: 6 | E11: Дмитрий РЫБАЛКИН | F11: 0.90347222 | H11: xx:xx
A12: 45857 | B12: Орехово-Зуево | C12: 16 | D12: 10 | E12: Владимир ГОЛОКОЛОСОВ | F12: 0.77013889 | G12: Анна ПАВЛОВА | H12: 1.0076389
A13: 45857 | B13: Подольск | C13: 24 | D13: 10 | E13: Денис РЯДНЫХ | F13: 0.75208333 | G13: Ксения РОМАНОВА | H13: 0.95138889
A14: 45857 | B14: Тверь | C14: 44 | D14: 11 | E14: Антон БОЛДИНЮК | F14: 0.75972222 | G14: Мария ЕЖУНОВА | H14: 0.99097222
A15: 45857 | B15: Саранск | C15: 36 | D15: 10 | E15: Альберт ЛАТЫШЕВ | F15: 0.76111111 | G15: Вероника НЕКАЕВА | H15: 0.75555556
A16: 45857 | B16: Пристань Печатники | C16: 27 | D16: 18 | E16: Леонид КОРОЛЁВ | F16: 0.78819444 | G16: Дарья ОДИНОКИХ | H16: 0.97708333
A17: 45857 | B17: Пенза | C17: 35 | D17: 11 | E17: Алексей ФИЛИН | F17: 0.94375 | G17: Юлия ОТТО | H17: 1.01875
A18: 45857 | B18: Ленск | C18: 17 | D18: 12 | E18: Александр ОСТАПОВ | F18: 0.69166667 | G18: Екатерина ХОРЗОВА | H18: 1.0159722
A19: 45857 | B19: Троицк | C19: 15 | D19: 7 | E19: Денис ТУРОЧКА | F19: 0.92777778 | G19: Армине МЕЛИКЯН | H19: 1.6222222
A20: 45857 | B20: Хабаровск | C20: 20 | D20: 5 | E20: Иван АНЦИФЕРОВ | F20: 1.0729167 | G20: Светлана СИРОТА | H20: 1.0222222
A21: 45857 | B21: Царицыно | C21: 39 | D21: 16 | E21: Александр РАСПЕРТОВ | F21: 0.78402778 | G21: Светлана ТЕРЕШОНКОВА | H21: 1.0020833
A22: 45857 | B22: Щёлково | C22: 13 | D22: 10 | E22: Амаяк ГЕВОРГЯН | F22: 0.92152778 | G22: Валерия ШАМАЕВА | H22: 1.1375
A24: 45857 | B24: Belgrade | C24: 11 | D24: 7 | E24: Дмитрий КУСТЕРСКИЙ | F24: 0.86111111 | G24: Viktoriia KAZANTSEVA | H24: 1.1847222
... A28: 45857 | B28: Гомель | C28: 16 | D28: 5 | E28: Евгений МАГОНОВ | F28: 0.85902778 | G28: Диана ЛАСИЦА | H28: 1.28125

Sheet Лист3
A1: 45850 | B1: Ангарские пруды | C1: 29 | D1: 14 | E1: Максим ЕРМАКОВ | F1: 0.81458333 | G1: Ирина КОПЫЛОВА | H1: 1.0513889
A2: 45850 | B2: Гольяново | C2: 10 | D2: 6 | E2: Ренат ХУДАЙБЕРДИН | F2: 0.95625 | G2: Алла КУНИНА | H2: 1.0361111
A3: 45850 | B3: Валдай | C3: 26 | D3: 7 | E3: Евгений РЫБИНСКИЙ | F3: 0.74791667 | G3: Мария БАРУЦКОВА | H3: 0.90625
A4: 45850 | B4: Иваново | C4: 23 | D4: 4 | E4: Андрей МАСЛОВ | F4: 0.78472222 | G4: Диана ПЫХОВА | H4: 1.2493056
A5: 45850 | B5: Екатерининский | C5: 5 | D5: 15 | E5: Рaмиль ЯХYДИН | F5: 1.8416667 | G5: Елена ВЛАСОВА | H5: 1.3333333
A6: 45850 | B6: Измайлово | C6: 164 | D6: 31 | E6: Николай ШЛЫКОВ | F6: 0.67986111 | G6: Елена КИРЕЕВА | H6: 0.82222222
A7: 45850 | B7: Кузьминки | C7: 98 | D7: 28 | E7: Дмитрий ТИХОНОВ | F7: 0.71319444 | G7: Алина ПЕТРУК | H7: 0.93819444
A8: 45850 | B8: Кусково | C8: 17 | D8: 15 | E8: Андрей ПОТАШОВ | F8: 0.85763889 | G8: Яна ВОРОБЬЕВА | H8: 1.1701389
A9: 45850 | B9: Олимпийская Деревня | C9: 7 | D9: 6 | E9: Максим ТИНЬКОВ | F9: 0.86041667 | G9: Татьяна КОЛЕСНИКОВА | H9: 1.4305556
A10: 45850 | B10: Орехово-Зуево | C10: 13 | D10: 11 | E10: Владимир ГОЛОКОЛОСОВ | F10: 0.80763889 | G10: Елена ТИМОФЕЕВА | H10: 1.2069444
A11: 45850 | B11: Подольск | C11: 15 | D11: 7 | E11: Денис РЯДНЫХ | F11: 0.75416667 | G11: Ольга БАЙРАШЕВА | H11: 1.2444444
A12: 45850 | B12: Тверь | C12: 44 | D12: 11 | E12: Антон БОЛДИНЮК | F12: 0.76041667 | G12: Дарья ЦВЕТКОВА | H12: 0.90902778
... A28: 45850 | B28: Гомель | C28: 16 | D28: 3 | E28: Александр БУЛАВИНСКИЙ | F28: 0.76666667 | G28: Светлана ЯРОВАЯ | H28: 1.0375

Sheet Лист4
A1: 45759 | B1: Ангарские пруды | C1: 58 | D1: 16 | E1: Максим МАХНО | F1: 0.78819444 | G1: Юна КРАВЧЕНКО | H1: 1.0020833
A2: 45759 | B2: Великий Новгород | C2: 93 | D2: 13 | E2: Александр КИРИЛЛОВ | F2: 0.79791667 | G2: Анастасия Алексеева | H2: 0.95138889
A3: 45759 | B3: Гольяново | C3: 11 | D3: 5 | E3: Сергей БАБУШИНОВ | F3: 0.74513889 | G3: Алла КУНИНА | H3: 0.97430556
A4: 45759 | B4: Екатерининский | C4: 7 | D4: 24 | E4: Ренат НУРИМАНОВ | F4: 0.87986111 | G4: Ксения АБРАМОВА | H4: 0.98333333
A5: 45759 | B5: Иваново | C5: 15 | D5: 4 | E5: Владислав ЮШИНОВ | F5: 0.86944444 | G5: Мария УДАЛОВА | H5: 1.0298611
A6: 45759 | B6: Измайлово | C6: 45 | D6: 18 | E6: Сергей НАЗИН | F6: 0.74791667 | G6: Ирина КИРДЯШКИНА | H6: 0.97638889
A7: 45759 | B7: Кузьминки | C7: 95 | D7: 32 | E7: Юрий ВОЛОДИН | F7: 0.74722222 | G7: Светлана БРЕДИХИНА | H7: 0.92291667
A8: 45759 | B8: Кусково | C8: 29 | D8: 15 | E8: Семен КАЮМОВ | F8: 0.82083333 | G8: Елизавета ГОЛУБЕВА | H8: 1.0416667
A9: 45759 | B9: Орехово-Зуево | C9: 21 | D9: 13 | E9: Петр ЯРЕМЕНКО | F9: 0.80972222 | G9: Наталья ДРЯГИНА | H9: 0.94305556
A10: 45759 | B10: Тверь | C10: 39 | D10: 9 | E10: Роман ЦВЕТКОВ | F10: 0.78611111 | G10: Яна ЗАХАРОВА | H10: 0.93472222
A11: 45759 | B11: Олимпийская Деревня | C11: 18 | D11: 13 | E11: Альберт КАРИМОВ | F11: 0.8875 | G11: Елена БЕЛАВИНА | H11: 1.0201389
A12: 45759 | B12: Саранск | C12: 19 | D12: 4 | E12: Степан НУДИПЛОДОВ | F12: 0.91319444 | G12: Людмила БЕГАЕВА | H12: 1.1729167
... A22: 45759 | B22: Novi Sad | C22: 12 | D22: 5 | E22: Rustam FAKHRETDINOV | F22: 0.83541667 | G22: Elena KAMENTSEVA | H22: 1.0770833
C23: =SUM(C1:C22) -> 723 | D23: =SUM(D1:D22) -> 270

Sheet Кузьминки
A1: 2022 | B1: =SUM('ОСНОВА'!E185:E227) -> 3825 | C1: =B1 -> 3825 | D1: 0
A2: 2023 | B2: =SUM('ОСНОВА'!E132:E184) -> 5364 | C2: =B2 -> 5364 | D2: 0
A3: 2024 | B3: =SUM('ОСНОВА'!E79:E131) -> 7347 | C3: =B3 -> 7347 | D3: 0
A4: 2025 | B4: =SUM('ОСНОВА'!E5:E78) -> 13174 | C4: =B4 -> 13174 | D4: ='ОСНОВА'!E4*2 -> 268.86878

Sheet измайлово
A1: 2022 | B1: =SUM('ОСНОВА'!I185:I211) -> 596 | C1: =B1 -> 596 | D1: 0
A2: 2023 | B2: =SUM('ОСНОВА'!I132:I184) -> 2172 | C2: =B2 -> 2172 | D2: 0
A3: 2024 | B3: =SUM('ОСНОВА'!I79:I131) -> 2587 | C3: =B3 -> 2587 | D3: 0
A4: 2025 | B4: =SUM('ОСНОВА'!I5:I78) -> 3288 | C4: =B4 -> 3288 | D4: ='ОСНОВА'!I4*2 -> 85.152709

Sheet царицыно
A1: 2022 | B1: =SUM('ОСНОВА'!H185:H211) -> 850 | C1: =B1*5 -> 4250 | D1: 0
A2: 2023 | B2: =SUM('ОСНОВА'!H132:H184) -> 1961 | C2: =B2*5 -> 9805 | D2: 0
A3: 2024 | B3: =SUM('ОСНОВА'!H79:H131) -> 1778 | C3: =B3*5 -> 8890 | D3: 0
A4: 2025 | B4: =SUM('ОСНОВА'!H5:H78) -> 2833 | C4: =B4*5 -> 14165 | D4: ='ОСНОВА'!H4*6*5 -> 1113.3
B17: =C3-C4 -> -5275 | C17: =B17/5 -> -1055 | D17: =C17/6 -> -175.83333
B19: 7725 | D19: =B19*5 -> 38625
A20: =B20/8 -> 154.875 | B20: =C20/5 -> 1239 | C20: 6195

Sheet кусково
A1: 2022 | B1: =SUM('ОСНОВА'!F185:F188) -> 185 | C1: =B1*5 -> 925 | D1: 0
A2: 2023 | B2: =SUM('ОСНОВА'!F132:F184) -> 2035 | C2: =B2*5 -> 10175 | D2: 0
A3: 2024 | B3: =SUM('ОСНОВА'!F79:F131) -> 1888 | C3: =B3*5 -> 9440 | D3: 0
A4: 2025 | B4: =SUM('ОСНОВА'!F5:F78) -> 2888 | C4: =B4*5 -> 14440 | D4: ='ОСНОВА'!F4*6*5 -> 1166
B17: =C3-C4 -> -5000 | C17: =B17/5 -> -1000 | D17: =C17/6 -> -166.66667
B19: 7725 | D19: =B19*5 -> 38625
A20: =B20/8 -> 154.875 | B20: =C20/5 -> 1239 | C20: 6195

Sheet Троицк
A1: 2022 | B1: =SUM('ОСНОВА'!J185:J227) -> 0 | C1: =B1*5 -> 0 | D1: 0
A2: 2023 | B2: =SUM('ОСНОВА'!J132:J184) -> 1602 | C2: =B2*5 -> 8010 | D2: 0
A3: 2024 | B3: =SUM('ОСНОВА'!J79:J131) -> 1875 | C3: =B3*5 -> 9375 | D3: 0
A4: 2025 | B4: =SUM('ОСНОВА'!J5:J78) -> 2566 | C4: =B4*5 -> 12830 | D4: =30*6*5 -> 900
B17: =C3-C4 -> -3455 | C17: =B17/5 -> -691 | D17: =C17/6 -> -115.16667
B19: 7725 | D19: =B19*5 -> 38625
A20: =B20/8 -> 154.875 | B20: =C20/5 -> 1239 | C20: 6195

Sheet Печатники
A1: 2022 | B1: =SUM('ОСНОВА'!K185:K227) -> 0 | C1: =B1*5 -> 0 | D1: 0
A2: 2023 | B2: =SUM('ОСНОВА'!K132:K184) -> 0 | C2: =B2*5 -> 0 | D2: 0
A3: 2024 | B3: =SUM('ОСНОВА'!K79:K131) -> 795 | C3: =B3 -> 795 | D3: 0
A4: 2025 | B4: =SUM('ОСНОВА'!K5:K78) -> 2117 | C4: =B4 -> 2117 | D4: ='ОСНОВА'!K4 -> 30.652632
B17: =C3-C4 -> -1322 | C17: =B17/5 -> -264.4 | D17: =C17/6 -> -44.066667
B19: 7725 | D19: =B19*5 -> 38625
A20: =B20/8 -> 154.875 | B20: =C20/5 -> 1239 | C20: 6195

Sheet Иваново
A1: 2022 | B1: =SUM('ОСНОВА'!K185:K227) -> 0 | C1: =B1*5 -> 0 | D1: 0
A2: 2023 | B2: =SUM('ОСНОВА'!V132:V184) -> 332 | C2: =B2 -> 332 | D2: 0
A3: 2024 | B3: =SUM('ОСНОВА'!V79:V131) -> 867 | C3: =B3 -> 867 | D3: 0
A4: 2025 | B4: =SUM('ОСНОВА'!V5:V78) -> 2296 | C4: =B4 -> 2296 | D4: ='ОСНОВА'!V4 -> 22.993421
B17: =C3-C4 -> -1429 | C17: =B17/5 -> -285.8 | D17: =C17/6 -> -47.633333
B19: 7725 | D19: =B19*5 -> 38625
A20: =B20/8 -> 154.875 | B20: =C20/5 -> 1239 | C20: 6195

Sheet Лист10
A2: 1614 | B2: 627 | C2: =SUM(A2:B2) -> 2241
A3: 2141 | B3: 738 | C3: =SUM(A3:B3) -> 2879
A4: 2395 | B4: 824 | C4: =SUM(A4:B4) -> 3219
A5: 1860 | B5: 689 | C5: =SUM(A5:B5) -> 2549
A6: 2967 | B6: 930 | C6: =SUM(A6:B6) -> 3897
A7: 1864 | B7: 734 | C7: =SUM(A7:B7) -> 2598
A8: 2136 | B8: 911 | C8: =SUM(A8:B8) -> 3047
A9: 2529 | B9: 787 | C9: =SUM(A9:B9) -> 3316
A10: 2203 | B10: 805 | C10: =SUM(A10:B10) -> 3008
A11: 1889 | B11: 771 | C11: =SUM(A11:B11) -> 2660
A12: 2035 | B12: 794 | C12: =SUM(A12:B12) -> 2829
A13: 1092 | B13: 390 | C13: =SUM(A13:B13) -> 1482

Sheet среднее по РФ
A1: 2022 | B1: =AVERAGE('ОСНОВА'!AJ185:AJ227) -> 37.810078
A2: 2023 | B2: =AVERAGE('ОСНОВА'!AJ132:AJ184) -> 36.616538
A3: 2024 | B3: =AVERAGE('ОСНОВА'!AJ79:AJ131) -> 36.497967
A4: 2025 | B4: =AVERAGE('ОСНОВА'!AJ26:AJ78) -> 38.821275
